<robot name = "robot">
    <link name="0">
        <inertial>
            <origin xyz="0 0 0.12095191509253811" rpy="0 0 0"/>
            <mass value="0.002419038301850763" />
            <inertia ixx="100" ixy="0" ixz="0" iyy="100" iyz="0" izz="100" />
        </inertial>
        <visual>
            <origin xyz="0 0 0.12095191509253811" rpy="0 0 0"/>
            <geometry>
                <box size="0.1 0.1 0.24190383018507622" />
            </geometry>
            <material name="Blue">
                <color rgba="0 0 1.0 1.0"/>
            </material>
        </visual>
        <collision>
            <origin xyz="0 0 0.12095191509253811" rpy="0 0 0"/>
            <geometry>
                <box size="0.1 0.1 0.24190383018507622" />
            </geometry>
        </collision>
    </link>
    <joint name="0_1" type="revolute">
       <parent link="0"/>
       <child  link="1"/>
       <origin rpy="0 0 0" xyz="-0.05 0 0.12095191509253811" />
     <axis xyz="0 1 0"/>
       <limit effort="0.0" lower="-3.14159" upper="3.14159" velocity="0.0"/>
    </joint>
    <link name="1">
        <inertial>
            <origin xyz="-0.05192864885733617 0 0" rpy="0 0 0"/>
            <mass value="0.0035479292282532444" />
            <inertia ixx="100" ixy="0" ixz="0" iyy="100" iyz="0" izz="100" />
        </inertial>
        <visual>
            <origin xyz="-0.05192864885733617 0 0" rpy="0 0 0"/>
            <geometry>
                <box size="0.10385729771467234 0.21732509132161126 0.15719113834563692" />
            </geometry>
            <material name="Green">
                <color rgba="0 1.0 0 1.0"/>
            </material>
        </visual>
        <collision>
            <origin xyz="-0.05192864885733617 0 0" rpy="0 0 0"/>
            <geometry>
                <box size="0.10385729771467234 0.21732509132161126 0.15719113834563692" />
            </geometry>
        </collision>
    </link>
    <joint name="1_2" type="revolute">
       <parent link="1"/>
       <child  link="2"/>
       <origin rpy="0 0 0" xyz="-0.10385729771467234 0 0" />
     <axis xyz="0 1 0"/>
       <limit effort="0.0" lower="-3.14159" upper="3.14159" velocity="0.0"/>
    </joint>
    <link name="2">
        <inertial>
            <origin xyz="-0.17197719969425052 0 0" rpy="0 0 0"/>
            <mass value="0.00305754476619518" />
            <inertia ixx="100" ixy="0" ixz="0" iyy="100" iyz="0" izz="100" />
        </inertial>
        <visual>
            <origin xyz="-0.17197719969425052 0 0" rpy="0 0 0"/>
            <geometry>
                <box size="0.34395439938850103 0.41850912007422664 0.02124061216360118" />
            </geometry>
            <material name="Blue">
                <color rgba="0 0 1.0 1.0"/>
            </material>
        </visual>
        <collision>
            <origin xyz="-0.17197719969425052 0 0" rpy="0 0 0"/>
            <geometry>
                <box size="0.34395439938850103 0.41850912007422664 0.02124061216360118" />
            </geometry>
        </collision>
    </link>
    <joint name="2_3" type="revolute">
       <parent link="2"/>
       <child  link="3"/>
       <origin rpy="0 0 0" xyz="-0.34395439938850103 0 0" />
     <axis xyz="0 1 0"/>
       <limit effort="0.0" lower="-3.14159" upper="3.14159" velocity="0.0"/>
    </joint>
    <link name="3">
        <inertial>
            <origin xyz="-0.1440360877266856 0 0" rpy="0 0 0"/>
            <mass value="0.018451281141038833" />
            <inertia ixx="100" ixy="0" ixz="0" iyy="100" iyz="0" izz="100" />
        </inertial>
        <visual>
            <origin xyz="-0.1440360877266856 0 0" rpy="0 0 0"/>
            <geometry>
                <box size="0.2880721754533712 0.26477834853863336 0.24190383018507622" />
            </geometry>
            <material name="Blue">
                <color rgba="0 0 1.0 1.0"/>
            </material>
        </visual>
        <collision>
            <origin xyz="-0.1440360877266856 0 0" rpy="0 0 0"/>
            <geometry>
                <box size="0.2880721754533712 0.26477834853863336 0.24190383018507622" />
            </geometry>
        </collision>
    </link>
    <joint name="3_4" type="revolute">
       <parent link="3"/>
       <child  link="4"/>
       <origin rpy="0 0 0" xyz="-0.2880721754533712 0 0" />
     <axis xyz="0 1 0"/>
       <limit effort="0.0" lower="-3.14159" upper="3.14159" velocity="0.0"/>
    </joint>
    <link name="4">
        <inertial>
            <origin xyz="-0.07798299330358435 0 0" rpy="0 0 0"/>
            <mass value="0.008182334508450231" />
            <inertia ixx="100" ixy="0" ixz="0" iyy="100" iyz="0" izz="100" />
        </inertial>
        <visual>
            <origin xyz="-0.07798299330358435 0 0" rpy="0 0 0"/>
            <geometry>
                <box size="0.1559659866071687 0.21687255133037775 0.24190383018507622" />
            </geometry>
            <material name="Green">
                <color rgba="0 1.0 0 1.0"/>
            </material>
        </visual>
        <collision>
            <origin xyz="-0.07798299330358435 0 0" rpy="0 0 0"/>
            <geometry>
                <box size="0.1559659866071687 0.21687255133037775 0.24190383018507622" />
            </geometry>
        </collision>
    </link>
    <joint name="4_5" type="revolute">
       <parent link="4"/>
       <child  link="5"/>
       <origin rpy="0 0 0" xyz="-0.1559659866071687 0 0" />
     <axis xyz="0 1 0"/>
       <limit effort="0.0" lower="-3.14159" upper="3.14159" velocity="0.0"/>
    </joint>
    <link name="5">
        <inertial>
            <origin xyz="-0.23776006360992163 0 0" rpy="0 0 0"/>
            <mass value="0.02565017897110692" />
            <inertia ixx="100" ixy="0" ixz="0" iyy="100" iyz="0" izz="100" />
        </inertial>
        <visual>
            <origin xyz="-0.23776006360992163 0 0" rpy="0 0 0"/>
            <geometry>
                <box size="0.47552012721984327 0.22504608659095526 0.23969006353758793" />
            </geometry>
            <material name="Blue">
                <color rgba="0 0 1.0 1.0"/>
            </material>
        </visual>
        <collision>
            <origin xyz="-0.23776006360992163 0 0" rpy="0 0 0"/>
            <geometry>
                <box size="0.47552012721984327 0.22504608659095526 0.23969006353758793" />
            </geometry>
        </collision>
    </link>
    <joint name="5_6" type="revolute">
       <parent link="5"/>
       <child  link="6"/>
       <origin rpy="0 0 0" xyz="-0.47552012721984327 0 0" />
     <axis xyz="0 1 0"/>
       <limit effort="0.0" lower="-3.14159" upper="3.14159" velocity="0.0"/>
    </joint>
    <link name="6">
        <inertial>
            <origin xyz="-0.05 0 0" rpy="0 0 0"/>
            <mass value="0.004380931842327791" />
            <inertia ixx="100" ixy="0" ixz="0" iyy="100" iyz="0" izz="100" />
        </inertial>
        <visual>
            <origin xyz="-0.05 0 0" rpy="0 0 0"/>
            <geometry>
                <box size="0.1 0.4960074192404221 0.08832391759455294" />
            </geometry>
            <material name="Green">
                <color rgba="0 1.0 0 1.0"/>
            </material>
        </visual>
        <collision>
            <origin xyz="-0.05 0 0" rpy="0 0 0"/>
            <geometry>
                <box size="0.1 0.4960074192404221 0.08832391759455294" />
            </geometry>
        </collision>
    </link>
    <joint name="6_7" type="revolute">
       <parent link="6"/>
       <child  link="7"/>
       <origin rpy="0 0 0" xyz="-0.1 0 0" />
     <axis xyz="0 1 0"/>
       <limit effort="0.0" lower="-3.14159" upper="3.14159" velocity="0.0"/>
    </joint>
    <link name="7">
        <inertial>
            <origin xyz="-0.1614806288344342 0 0" rpy="0 0 0"/>
            <mass value="0.01616710335193102" />
            <inertia ixx="100" ixy="0" ixz="0" iyy="100" iyz="0" izz="100" />
        </inertial>
        <visual>
            <origin xyz="-0.1614806288344342 0 0" rpy="0 0 0"/>
            <geometry>
                <box size="0.3229612576688684 0.2069374257200875 0.24190383018507622" />
            </geometry>
            <material name="Green">
                <color rgba="0 1.0 0 1.0"/>
            </material>
        </visual>
        <collision>
            <origin xyz="-0.1614806288344342 0 0" rpy="0 0 0"/>
            <geometry>
                <box size="0.3229612576688684 0.2069374257200875 0.24190383018507622" />
            </geometry>
        </collision>
    </link>
</robot>