<robot name = "robot">
    <link name="0">
        <inertial>
            <origin xyz="0 0 0.5" rpy="0 0 0"/>
            <mass value="0.2804297768758938" />
            <inertia ixx="100" ixy="0" ixz="0" iyy="100" iyz="0" izz="100" />
        </inertial>
        <visual>
            <origin xyz="0 0 0.5" rpy="0 0 0"/>
            <geometry>
                <box size="0.9861102302435957 0.5687594921444434 0.5" />
            </geometry>
            <material name="Blue">
                <color rgba="0 0 1.0 1.0"/>
            </material>
        </visual>
        <collision>
            <origin xyz="0 0 0.5" rpy="0 0 0"/>
            <geometry>
                <box size="0.9861102302435957 0.5687594921444434 0.5" />
            </geometry>
        </collision>
    </link>
    <joint name="0_1" type="revolute">
       <parent link="0"/>
       <child  link="1"/>
       <origin rpy="0 0 0" xyz="-0.49305511512179784 0 0.5" />
     <axis xyz="0 1 0"/>
       <limit effort="0.0" lower="-3.14159" upper="3.14159" velocity="0.0"/>
    </joint>
    <link name="1">
        <inertial>
            <origin xyz="-0.3381775152562398 0 0" rpy="0 0 0"/>
            <mass value="0.2765398091829991" />
            <inertia ixx="100" ixy="0" ixz="0" iyy="100" iyz="0" izz="100" />
        </inertial>
        <visual>
            <origin xyz="-0.3381775152562398 0 0" rpy="0 0 0"/>
            <geometry>
                <box size="0.6763550305124796 0.8177356468346592 0.5" />
            </geometry>
            <material name="Blue">
                <color rgba="0 0 1.0 1.0"/>
            </material>
        </visual>
        <collision>
            <origin xyz="-0.3381775152562398 0 0" rpy="0 0 0"/>
            <geometry>
                <box size="0.6763550305124796 0.8177356468346592 0.5" />
            </geometry>
        </collision>
    </link>
    <joint name="1_2" type="revolute">
       <parent link="1"/>
       <child  link="2"/>
       <origin rpy="0 0 0" xyz="-0.6763550305124796 0 0" />
     <axis xyz="0 1 0"/>
       <limit effort="0.0" lower="-3.14159" upper="3.14159" velocity="0.0"/>
    </joint>
    <link name="2">
        <inertial>
            <origin xyz="-0.3782071802154232 0 0" rpy="0 0 0"/>
            <mass value="0.2774544189270528" />
            <inertia ixx="100" ixy="0" ixz="0" iyy="100" iyz="0" izz="100" />
        </inertial>
        <visual>
            <origin xyz="-0.3782071802154232 0 0" rpy="0 0 0"/>
            <geometry>
                <box size="0.7564143604308464 0.7336043138287787 0.5" />
            </geometry>
            <material name="Green">
                <color rgba="0 1.0 0 1.0"/>
            </material>
        </visual>
        <collision>
            <origin xyz="-0.3782071802154232 0 0" rpy="0 0 0"/>
            <geometry>
                <box size="0.7564143604308464 0.7336043138287787 0.5" />
            </geometry>
        </collision>
    </link>
    <joint name="2_3" type="revolute">
       <parent link="2"/>
       <child  link="3"/>
       <origin rpy="0 0 0" xyz="-0.7564143604308464 0 0" />
     <axis xyz="0 1 0"/>
       <limit effort="0.0" lower="-3.14159" upper="3.14159" velocity="0.0"/>
    </joint>
    <link name="3">
        <inertial>
            <origin xyz="-0.25 0 0" rpy="0 0 0"/>
            <mass value="0.3654554231966683" />
            <inertia ixx="100" ixy="0" ixz="0" iyy="100" iyz="0" izz="100" />
        </inertial>
        <visual>
            <origin xyz="-0.25 0 0" rpy="0 0 0"/>
            <geometry>
                <box size="0.5 0.8676198679527402 0.8424321219360894" />
            </geometry>
            <material name="Blue">
                <color rgba="0 0 1.0 1.0"/>
            </material>
        </visual>
        <collision>
            <origin xyz="-0.25 0 0" rpy="0 0 0"/>
            <geometry>
                <box size="0.5 0.8676198679527402 0.8424321219360894" />
            </geometry>
        </collision>
    </link>
    <joint name="3_4" type="revolute">
       <parent link="3"/>
       <child  link="4"/>
       <origin rpy="0 0 0" xyz="-0.5 0 0" />
     <axis xyz="0 1 0"/>
       <limit effort="0.0" lower="-3.14159" upper="3.14159" velocity="0.0"/>
    </joint>
    <link name="4">
        <inertial>
            <origin xyz="-0.4605367616452085 0 0" rpy="0 0 0"/>
            <mass value="0.6009139294441457" />
            <inertia ixx="100" ixy="0" ixz="0" iyy="100" iyz="0" izz="100" />
        </inertial>
        <visual>
            <origin xyz="-0.4605367616452085 0 0" rpy="0 0 0"/>
            <geometry>
                <box size="0.921073523290417 0.8682577880158933 0.7513967032982304" />
            </geometry>
            <material name="Green">
                <color rgba="0 1.0 0 1.0"/>
            </material>
        </visual>
        <collision>
            <origin xyz="-0.4605367616452085 0 0" rpy="0 0 0"/>
            <geometry>
                <box size="0.921073523290417 0.8682577880158933 0.7513967032982304" />
            </geometry>
        </collision>
    </link>
    <joint name="4_5" type="revolute">
       <parent link="4"/>
       <child  link="5"/>
       <origin rpy="0 0 0" xyz="-0.921073523290417 0 0" />
     <axis xyz="0 1 0"/>
       <limit effort="0.0" lower="-3.14159" upper="3.14159" velocity="0.0"/>
    </joint>
    <link name="5">
        <inertial>
            <origin xyz="-0.36470368317717144 0 0" rpy="0 0 0"/>
            <mass value="0.23651459783539994" />
            <inertia ixx="100" ixy="0" ixz="0" iyy="100" iyz="0" izz="100" />
        </inertial>
        <visual>
            <origin xyz="-0.36470368317717144 0 0" rpy="0 0 0"/>
            <geometry>
                <box size="0.7294073663543429 0.6485116787825315 0.5" />
            </geometry>
            <material name="Blue">
                <color rgba="0 0 1.0 1.0"/>
            </material>
        </visual>
        <collision>
            <origin xyz="-0.36470368317717144 0 0" rpy="0 0 0"/>
            <geometry>
                <box size="0.7294073663543429 0.6485116787825315 0.5" />
            </geometry>
        </collision>
    </link>
    <joint name="5_6" type="revolute">
       <parent link="5"/>
       <child  link="6"/>
       <origin rpy="0 0 0" xyz="-0.7294073663543429 0 0" />
     <axis xyz="0 1 0"/>
       <limit effort="0.0" lower="-3.14159" upper="3.14159" velocity="0.0"/>
    </joint>
    <link name="6">
        <inertial>
            <origin xyz="-0.25 0 0" rpy="0 0 0"/>
            <mass value="0.30775434736297347" />
            <inertia ixx="100" ixy="0" ixz="0" iyy="100" iyz="0" izz="100" />
        </inertial>
        <visual>
            <origin xyz="-0.25 0 0" rpy="0 0 0"/>
            <geometry>
                <box size="0.5 0.7942231752985267 0.7749820376301587" />
            </geometry>
            <material name="Blue">
                <color rgba="0 0 1.0 1.0"/>
            </material>
        </visual>
        <collision>
            <origin xyz="-0.25 0 0" rpy="0 0 0"/>
            <geometry>
                <box size="0.5 0.7942231752985267 0.7749820376301587" />
            </geometry>
        </collision>
    </link>
    <joint name="6_7" type="revolute">
       <parent link="6"/>
       <child  link="7"/>
       <origin rpy="0 0 0" xyz="-0.5 0 0" />
     <axis xyz="0 1 0"/>
       <limit effort="0.0" lower="-3.14159" upper="3.14159" velocity="0.0"/>
    </joint>
    <link name="7">
        <inertial>
            <origin xyz="-0.34740322368672705 0 0" rpy="0 0 0"/>
            <mass value="0.32294480384295404" />
            <inertia ixx="100" ixy="0" ixz="0" iyy="100" iyz="0" izz="100" />
        </inertial>
        <visual>
            <origin xyz="-0.34740322368672705 0 0" rpy="0 0 0"/>
            <geometry>
                <box size="0.6948064473734541 0.9295964511088459 0.5" />
            </geometry>
            <material name="Green">
                <color rgba="0 1.0 0 1.0"/>
            </material>
        </visual>
        <collision>
            <origin xyz="-0.34740322368672705 0 0" rpy="0 0 0"/>
            <geometry>
                <box size="0.6948064473734541 0.9295964511088459 0.5" />
            </geometry>
        </collision>
    </link>
    <joint name="7_8" type="revolute">
       <parent link="7"/>
       <child  link="8"/>
       <origin rpy="0 0 0" xyz="-0.6948064473734541 0 0" />
     <axis xyz="0 1 0"/>
       <limit effort="0.0" lower="-3.14159" upper="3.14159" velocity="0.0"/>
    </joint>
    <link name="8">
        <inertial>
            <origin xyz="-0.3800479082383494 0 0" rpy="0 0 0"/>
            <mass value="0.2555266954687705" />
            <inertia ixx="100" ixy="0" ixz="0" iyy="100" iyz="0" izz="100" />
        </inertial>
        <visual>
            <origin xyz="-0.3800479082383494 0 0" rpy="0 0 0"/>
            <geometry>
                <box size="0.7600958164766988 0.5698299085517651 0.5899601755191537" />
            </geometry>
            <material name="Blue">
                <color rgba="0 0 1.0 1.0"/>
            </material>
        </visual>
        <collision>
            <origin xyz="-0.3800479082383494 0 0" rpy="0 0 0"/>
            <geometry>
                <box size="0.7600958164766988 0.5698299085517651 0.5899601755191537" />
            </geometry>
        </collision>
    </link>
    <joint name="8_9" type="revolute">
       <parent link="8"/>
       <child  link="9"/>
       <origin rpy="0 0 0" xyz="-0.7600958164766988 0 0" />
     <axis xyz="0 1 0"/>
       <limit effort="0.0" lower="-3.14159" upper="3.14159" velocity="0.0"/>
    </joint>
    <link name="9">
        <inertial>
            <origin xyz="-0.25 0 0" rpy="0 0 0"/>
            <mass value="0.125" />
            <inertia ixx="100" ixy="0" ixz="0" iyy="100" iyz="0" izz="100" />
        </inertial>
        <visual>
            <origin xyz="-0.25 0 0" rpy="0 0 0"/>
            <geometry>
                <box size="0.5 0.5 0.5" />
            </geometry>
            <material name="Green">
                <color rgba="0 1.0 0 1.0"/>
            </material>
        </visual>
        <collision>
            <origin xyz="-0.25 0 0" rpy="0 0 0"/>
            <geometry>
                <box size="0.5 0.5 0.5" />
            </geometry>
        </collision>
    </link>
</robot>